<mujoco model="autobio_like">
  <asset>
    <mesh name="dish_mesh" file="meshes/dish.obj"/>
    <texture name="glass_texture" file="textures/glass.png" type="2d"/>
    <material name="glass" texture="glass_texture" rgba="0.8 0.9 1.0 0.35"/>
  </asset>
  <worldbody>
    <body name="sample" pos="0 0 0">
      <geom name="sample_geom" type="mesh" mesh="dish_mesh" material="glass"/>
      <joint name="slide" type="slide" axis="1 0 0" range="0 0.1"/>
      <site name="sensor_site"/>
      <body name="child" pos="0 0 0.02">
        <geom name="child_geom" type="sphere" size="0.01"/>
      </body>
    </body>
  </worldbody>
  <actuator>
    <motor name="slide_motor" joint="slide"/>
  </actuator>
  <sensor>
    <touch name="touch_sensor" site="sensor_site"/>
  </sensor>
  <contact>
    <pair geom1="sample_geom" geom2="child_geom"/>
  </contact>
  <equality>
    <weld name="lock" body1="sample" body2="child"/>
  </equality>
  <tendon>
    <spatial name="tendon"/>
  </tendon>
  <extension>
    <plugin plugin="custom.fluid"/>
  </extension>
</mujoco>
